Workbook

Sheet Read Me
A1: Workbook Guide
A2: Purpose, structure, definitions and controls
A4: Purpose | B4: Consolidated professional analysis of Mercado Pago account activity for April–August 2026.
A5: Coverage | B5: Five unique monthly statements: April, May, June, July and August 2026.
A6: Duplicate handling | B6: MercadoPago 4.pdf is a duplicate of the June statement and contributes no additional transactions.
A7: Transaction grain | B7: One row per unique operation ID.
A8: Amount convention | B8: Positive = inflow; negative = outflow.
A9: Balance | B9: Running account balance reported after each operation.
A10: Category logic | B10: Analytical classification based on the source description; it does not replace accounting treatment.
A11: Transfers | B11: Transfers to/from the account holder are kept separate from income/consumption.
A12: Credit card | B12: Card settlement is separated because the underlying purchases may belong to an earlier period.
A13: Judicial holds | B13: Court-ordered holds are kept separate from ordinary spending.
A14: Source fidelity | B14: April and May were transcribed from statement text supplied in chat; June–August were extracted from the uploaded PDFs.

Sheet USER_GUIDE
A1: USER GUIDE
A2: A simple guide to understanding and using this Mercado Pago workbook — no technical knowledge required
A4: START HERE — UNDER 5 MINUTES
A5: 1 | B5: Open Executive Summary for the headline totals, main topics, highlights, and recommended actions.
A6: 2 | B6: Open Trends & Insights to see monthly cash flow, low-balance risk, and the largest outflow categories.
A7: 3 | B7: Use Transactions only when you need to check a specific payment, date, category, counterparty, or balance.
A8: 4 | B8: Check Reconciliation before relying on the analysis: PASS means the monthly transaction totals agree with the statement.
A10: WHAT EACH SHEET IS FOR
A11: Sheet | B11: What you will find | E11: Use it when you want to…
A12: Read Me | B12: Scope, definitions, and source-handling rules. | E12: Understand how the workbook was prepared.
A13: Executive Summary | B13: A five-minute overview with totals, highlights, and actions. | E13: Get the answer quickly.
A14: Trends & Insights | B14: Charts, key indicators, monthly trends, and interpretation. | E14: See patterns and financial risks.
A15: Dashboard | B15: Headline indicators and a compact monthly snapshot. | E15: Monitor the account at a glance.
A16: Monthly Summary | B16: Opening, inflows, outflows, closing, net movement, and variances by month. | E16: Compare one month with another.
A17: Transactions | B17: All 326 unique operations with dates, descriptions, categories, and balances. | E17: Investigate a particular transaction.
A18: Outflow Categories | B18: Spending totals and shares by analytical category. | E18: Understand where money went.
A19: Counterparties | B19: Names grouped by transaction count and money moved. | E19: Find recurring or concentrated relationships.
A20: Reconciliation | B20: Checks against statement totals and the source register. | E20: Confirm completeness and duplicate handling.
A21: Analysis & Chat | B21: Detailed month-by-month analytical notes. | E21: Read the reasoning behind the conclusions.
A23: SIMPLE MONTHLY ROUTINE
A24: Step | B24: What to do | F24: Where to check
A25: 1 | B25: Confirm the new month appears and the transaction count looks reasonable. | F25: Dashboard / Monthly Summary
A26: 2 | B26: Confirm Reconciliation says PASS and all variances are zero. | F26: Reconciliation
A27: 3 | B27: Review the monthly net movement and minimum observed balance. | F27: Trends & Insights
A28: 4 | B28: Investigate unusually large payments or unfamiliar counterparties. | F28: Transactions / Counterparties
A29: 5 | B29: Update your cash-buffer and payment-timing actions if liquidity was tight. | F29: Executive Summary
A31: SAFE USE — WHAT YOU MAY AND MAY NOT CHANGE
A32: • Use filters and sorting in the data tables to find information; this does not change the underlying transactions.
A33: • You may add notes in a new blank column, but avoid overwriting existing formulas, table headers, operation IDs, or balances.
A34: • Do not delete rows that look duplicated unless the operation ID and source control have been checked first.
A35: • Treat transfers and credit-card settlements separately from ordinary consumption; combining them can distort spending.
A36: • If a reconciliation status stops showing PASS, pause and review the source and formulas before using the totals.
A38: PLAIN-LANGUAGE GLOSSARY
A39: Inflows | B39: Money entering the Mercado Pago account.
A40: Outflows | B40: Money leaving the account.
A41: Net movement | B41: Inflows minus outflows. Positive means cash increased; negative means cash decreased.
A42: Closing balance | B42: The account balance at the end of the month.
A43: Minimum balance | B43: The lowest balance observed after any transaction during the month.
A44: Reconciliation | B44: A check that calculated transaction totals match the statement totals.
A47: IMPORTANT LIMITATIONS
...

Sheet Executive Summary
A1: Mercado Pago — Executive Summary
A2: Five-minute guide to activity from April–August 2026 | 326 unique transactions
A4: Total Transactions | C4: Total Inflows | E4: Total Outflows | G4: Net Cash Movement
A5: =COUNTA(Transactions!D5:D330) -> 326 | C5: =SUMIFS(Transactions!E5:E330,Transactions!F5:F330,"Inflow") -> 105270.27 | E5: =-SUMIFS(Transactions!E5:E330,Transactions!F5:F330,"Outflow") -> 114588.63 | G5: =SUM(Transactions!E5:E330) -> -9318.36
A8: MAIN TOPICS
A9: Topic | B9: What it means / where to look
A10: Cash position | B10: Monthly openings, inflows, outflows, closing balances and net movement — Monthly Summary and Dashboard.
A11: Transaction detail | B11: 326 unique operations with date, category, counterparty and running balance — Transactions.
A12: Spending structure | B12: Outflows split between transfers, card settlements and ordinary consumption — Outflow Categories.
A13: Counterparties | B13: Recurring names and absolute flow concentration — Counterparties.
A14: Controls | B14: All five months reconcile; duplicate June source is excluded — Reconciliation.
A16: TOP HIGHLIGHTS
A17: • Net cash movement was −R$9,318.36: inflows of R$105,270.27 did not cover R$114,588.63 of outflows.
A18: • July was the weakest month (−R$19,796.12); June was strongest (+R$10,042.74). Only 2 of 5 months were negative.
A19: • Liquidity was tight every month: the observed minimum stayed below R$500, reaching R$0.00 in August.
A20: • Transfers plus credit-card settlements represented 67.1% of all outflows, so they should be separated from ordinary consumption.
A21: • All five monthly statements passed reconciliation; the duplicate June source does not inflate the 326-transaction total.
A24: ACTION ITEMS
A25: Priority | B25: Action | C25: Why it matters
A26: High | B26: Set a minimum operating cash buffer and alert threshold. | C26: All five months fell below R$500; four approached R$33 or less.
A27: High | B27: Schedule large card and bill payments against confirmed funding dates. | C27: The largest outflow was R$9,377.49; card settlements reached R$29,540.63.
A28: Medium | B28: Budget ordinary consumption separately from transfers and card settlements. | C28: Those two categories make up 67.1% of outflows and can distort spending analysis.
A29: Medium | B29: Review recurring personal transfers and standardize counterparty names. | C29: Name variants fragment the counterparty view and make recurring flows harder to monitor.
A30: Routine | B30: Continue monthly reconciliation and duplicate-source control. | C30: Current controls passed for every included month and should remain in place.

Sheet Trends & Insights
A1: Trends & Insights
A2: Cash flow, liquidity pressure and outflow concentration | April–August 2026
A4: STORY IN BRIEF
A5: The account ended the five-month period R$9,318.36 lower despite large, concentrated funding transfers.
A6: Monthly performance swung sharply: June added R$10,042.74, while July consumed R$19,796.12.
A7: Liquidity is the clearest risk signal: every month reached below R$500, and four months reached about R$33 or less.
A8: Transfers and card settlements dominate outflows, while ordinary spending is led by bills, groceries and e-commerce.
A10: Months Below R$500 | D10: Negative Months | G10: Transfer + Card Share | I10: Funding Concentration
A11: =COUNTIF(F15:F19,"<500") -> 5 | D11: =COUNTIF(D15:D19,"<0") -> 2 | G11: =SUM('Outflow Categories'!B5:B6)/SUM('Outflow Categories'!B5:B24) -> 0.67096072 | I11: =(SUMIFS(Transactions!E5:E330,Transactions!I5:I330,"EDUARDO F GIOVANNINI",Transactions!F5:F330,"Inflow")+SUMIFS(Transactions!E5:E330,Transactions!I5:I330,"EDUARDO FORSTER GIOVANNINI",Transactions!F5:F330,"Inflow"))/SUMIFS(Transactions!E5:E330,Transactions!F5:F330,"Inflow") -> 0.96228679
A14: Month | B14: Inflows | C14: Outflows | D14: Net | E14: Closing | F14: Minimum Balance
A15: ='Monthly Summary'!B5 -> April 2026 | B15: ='Monthly Summary'!H5 -> 27262.06 | C15: ='Monthly Summary'!I5 -> 21193.04 | D15: ='Monthly Summary'!J5 -> 6069.02 | E15: ='Monthly Summary'!F5 -> 27224.11 | F15: =Dashboard!H11 -> 30.9
A16: ='Monthly Summary'!B6 -> May 2026 | B16: ='Monthly Summary'!H6 -> 17065.63 | C16: ='Monthly Summary'!I6 -> 30217.29 | D16: ='Monthly Summary'!J6 -> -13151.66 | E16: ='Monthly Summary'!F6 -> 14072.45 | F16: =Dashboard!H12 -> 471.2
A17: ='Monthly Summary'!B7 -> June 2026 | B17: ='Monthly Summary'!H7 -> 24151.04 | C17: ='Monthly Summary'!I7 -> 14108.3 | D17: ='Monthly Summary'!J7 -> 10042.74 | E17: ='Monthly Summary'!F7 -> 24115.19 | F17: =Dashboard!H13 -> 0.88
A18: ='Monthly Summary'!B8 -> July 2026 | B18: ='Monthly Summary'!H8 -> 11272.89 | C18: ='Monthly Summary'!I8 -> 31069.01 | D18: ='Monthly Summary'!J8 -> -19796.12 | E18: ='Monthly Summary'!F8 -> 4319.07 | F18: =Dashboard!H14 -> 33.11
A19: ='Monthly Summary'!B9 -> August 2026 | B19: ='Monthly Summary'!H9 -> 25518.65 | C19: ='Monthly Summary'!I9 -> 18000.99 | D19: ='Monthly Summary'!J9 -> 7517.66 | E19: ='Monthly Summary'!F9 -> 11836.73 | F19: =Dashboard!H15 -> 0
A40: Outflow Category | B40: Amount | C40: Share
A41: ='Outflow Categories'!A5 -> Person / External Transfer | B41: ='Outflow Categories'!B5 -> 47343.84 | C41: ='Outflow Categories'!C5 -> 0.4131635
A42: ='Outflow Categories'!A6 -> Credit Card Settlement | B42: ='Outflow Categories'!B6 -> 29540.63 | C42: ='Outflow Categories'!C6 -> 0.25779722
A43: ='Outflow Categories'!A7 -> Bills & Services | B43: ='Outflow Categories'!B7 -> 9790.6 | C43: ='Outflow Categories'!C7 -> 0.085441287
A44: ='Outflow Categories'!A8 -> Groceries & Food | B44: ='Outflow Categories'!B8 -> 6716.58 | C44: ='Outflow Categories'!C8 -> 0.058614716
A45: ='Outflow Categories'!A9 -> E-commerce | B45: ='Outflow Categories'!B9 -> 4805.39 | C45: ='Outflow Categories'!C9 -> 0.041936011
A46: ='Outflow Categories'!A10 -> Travel | B46: ='Outflow Categories'!B10 -> 3529.31 | C46: ='Outflow Categories'!C10 -> 0.030799827
A56: KEY INSIGHTS
A57: 1. Cash-flow volatility is high: the gap between the best and worst monthly net movement is R$29,838.86.
A58: 2. Account-holder funding names supplied about 96.2% of inflows, indicating strong dependence on concentrated transfers.
A59: 3. Person/external transfers are the largest outflow category (R$47,343.84; 41.3%), followed by card settlements (R$29,540.63; 25.8%).
A60: 4. Among ordinary categories, bills & services (R$9,790.60) and groceries & food (R$6,716.58) are the largest.
A61: 5. Reconciliation quality is strong: all included months pass, and the duplicated June source is explicitly excluded.

Sheet Dashboard
A1: Mercado Pago — April to August 2026
A2: Professional transaction workbook | 5 unique months | June duplicate source excluded from transaction totals
A4: Total Transactions | C4: Total Inflows | E4: Total Outflows | G4: Net Cash Movement | I4: Investment Yield | K4: Min. Observed Balance
A5: 326 | C5: 105270.27 | E5: 114588.63 | G5: -9318.36 | I5: 251.08 | K5: 0
A9: Monthly Snapshot
A10: Month | B10: Transactions | C10: Opening | D10: Inflows | E10: Outflows | F10: Net | G10: Closing | H10: Minimum Balance | I10: Reconciliation
A11: 2026-04 | B11: 64 | C11: 21155.09 | D11: 27262.06 | E11: 21193.04 | F11: 6069.02 | G11: 27224.11 | H11: 30.9 | I11: PASS
A12: 2026-05 | B12: 76 | C12: 27224.11 | D12: 17065.63 | E12: 30217.29 | F12: -13151.66 | G12: 14072.45 | H12: 471.2 | I12: PASS
A13: 2026-06 | B13: 47 | C13: 14072.45 | D13: 24151.04 | E13: 14108.3 | F13: 10042.74 | G13: 24115.19 | H13: 0.88 | I13: PASS
A14: 2026-07 | B14: 69 | C14: 24115.19 | D14: 11272.89 | E14: 31069.01 | F14: -19796.12 | G14: 4319.07 | H14: 33.11 | I14: PASS
A15: 2026-08 | B15: 70 | C15: 4319.07 | D15: 25518.65 | E15: 18000.99 | F15: 7517.66 | G15: 11836.73 | H15: 0 | I15: PASS

Sheet Monthly Summary
A1: Monthly Summary
A2: Statement-level reported totals vs. transaction-level calculated totals
A4: Month | B4: Period | C4: Opening | D4: Reported Inflows | E4: Reported Outflows | F4: Closing | G4: Reconciliation | H4: Calculated Inflows | I4: Calculated Outflows | J4: Calculated Net | K4: Reported Net | L4: Variance Inflows | M4: Variance Outflows | N4: Variance Closing
A5: 2026-04 | B5: April 2026 | C5: 21155.09 | D5: 27262.06 | E5: 21193.04 | F5: 27224.11 | G5: PASS | H5: 27262.06 | I5: 21193.04 | J5: 6069.02 | K5: 6069.02 | L5: -3.6379788e-12 | M5: 0 | N5: -3.6379788e-12
A6: 2026-05 | B6: May 2026 | C6: 27224.11 | D6: 17065.63 | E6: 30217.29 | F6: 14072.45 | G6: PASS | H6: 17065.63 | I6: 30217.29 | J6: -13151.66 | K6: -13151.66 | L6: -3.6379788e-12 | M6: 0 | N6: -3.6379788e-12
A7: 2026-06 | B7: June 2026 | C7: 14072.45 | D7: 24151.04 | E7: 14108.3 | F7: 24115.19 | G7: PASS | H7: 24151.04 | I7: 14108.3 | J7: 10042.74 | K7: 10042.74 | L7: -3.6379788e-12 | M7: 0 | N7: 0
A8: 2026-07 | B8: July 2026 | C8: 24115.19 | D8: 11272.89 | E8: 31069.01 | F8: 4319.07 | G8: PASS | H8: 11272.89 | I8: 31069.01 | J8: -19796.12 | K8: -19796.12 | L8: 0 | M8: 3.6379788e-12 | N8: -3.6379788e-12
A9: 2026-08 | B9: August 2026 | C9: 4319.07 | D9: 25518.65 | E9: 18000.99 | F9: 11836.73 | G9: PASS | H9: 25518.65 | I9: 18000.99 | J9: 7517.66 | K9: 7517.66 | L9: 0 | M9: -3.6379788e-12 | N9: 3.6379788e-12

Sheet Transactions
A1: Transactions
A2: 326 unique transactions | June duplicate source excluded from transaction rows
A4: Month | B4: Date | C4: Description | D4: Operation ID | E4: Amount | F4: Direction | G4: Category | H4: Subcategory | I4: Counterparty | J4: Balance | K4: Source | L4: Amount Absolute | M4: Transaction Key | N4: Source Status
A5: 2026-04 | B5: 46113 | C5: Pix enviado Eva Bezerra da Silva Brandao | D5: 152151991553 | E5: -2080 | F5: Outflow | G5: Person / External Transfer | H5: Sent Pix | I5: Eva Bezerra da Silva Brandao | J5: 18916.94 | K5: User-supplied statement text | L5: 2080 | M5: 2026-04-152151991553 | N5: Unique transaction
A6: 2026-04 | B6: 46113 | C6: Pix enviado Marinaldo Domingos de Souza | D6: 152189207147 | E6: -700 | F6: Outflow | G6: Person / External Transfer | H6: Sent Pix | I6: Marinaldo Domingos de Souza | J6: 18216.94 | K6: User-supplied statement text | L6: 700 | M6: 2026-04-152189207147 | N6: Unique transaction
A7: 2026-04 | B7: 46113 | C7: Pagamento com QR Pix ESTACAO 89 COMERCIO VAREJISTA DE ALIMENTOS LTDA | D7: 152833636626 | E7: -113.8 | F7: Outflow | G7: Groceries & Food | H7: Groceries / food | I7: ESTACAO 89 COMERCIO VAREJISTA DE ALIMENTOS LTDA | J7: 21050.87 | K7: User-supplied statement text | L7: 113.8 | M7: 2026-04-152833636626 | N7: Unique transaction
A8: 2026-04 | B8: 46113 | C8: Pagamento com QR Pix EDGLEY DE SOUSA FORMIGA | D8: 152834775544 | E8: -53.93 | F8: Outflow | G8: Person / External Transfer | H8: Sent Pix | I8: EDGLEY DE SOUSA FORMIGA | J8: 20996.94 | K8: User-supplied statement text | L8: 53.93 | M8: 2026-04-152834775544 | N8: Unique transaction
A9: 2026-04 | B9: 46113 | C9: Rendimentos | D9: 1741805550939 | E9: 9.58 | F9: Inflow | G9: Investment Yield | H9: Rendimentos | I9: Mercado Pago / Investment | J9: 21164.67 | K9: User-supplied statement text | L9: 9.58 | M9: 2026-04-1741805550939 | N9: Unique transaction
A10: 2026-04 | B10: 46114 | C10: Pagamento com QR Pix IATA INTERNATIONAL AIR TRANSPORT ASSOCIATION | D10: 152210734999 | E10: -1422.71 | F10: Outflow | G10: Travel | H10: Travel | I10: IATA INTERNATIONAL AIR TRANSPORT ASSOCIATION | J10: 16802.56 | K10: User-supplied statement text | L10: 1422.71 | M10: 2026-04-152210734999 | N10: Unique transaction
A11: 2026-04 | B11: 46114 | C11: Pagamento com QR Pix COMPANHIA DE AGUA E ESGOTOS DA PARAIBA CAGEPA | D11: 152211492245 | E11: -227.03 | F11: Outflow | G11: Utilities | H11: Electricity / water | I11: COMPANHIA DE AGUA E ESGOTOS DA PARAIBA CAGEPA | J11: 16575.53 | K11: User-supplied statement text | L11: 227.03 | M11: 2026-04-152211492245 | N11: Unique transaction
A12: 2026-04 | B12: 46114 | C12: Pix enviado Eduardo Silva dos Santos | D12: 152285797203 | E12: -350 | F12: Outflow | G12: Person / External Transfer | H12: Sent Pix | I12: Eduardo Silva dos Santos | J12: 16113.26 | K12: User-supplied statement text | L12: 350 | M12: 2026-04-152285797203 | N12: Unique transaction
A13: 2026-04 | B13: 46114 | C13: Pagamento com QR Pix REDE MENOR PRECO SUPERMERCADO LTDA | D13: 152309349407 | E13: -253.88 | F13: Outflow | G13: Groceries & Food | H13: Groceries / food | I13: REDE MENOR PRECO SUPERMERCADO LTDA | J13: 15791.59 | K13: User-supplied statement text | L13: 253.88 | M13: 2026-04-152309349407 | N13: Unique transaction
A14: 2026-04 | B14: 46114 | C14: Pix enviado Estacao 89 Comercio Varejista de Alimentos Ltda | D14: 152317783031 | E14: -75.5 | F14: Outflow | G14: Groceries & Food | H14: Groceries / food | I14: Estacao 89 Comercio Varejista de Alimentos Ltda | J14: 15716.09 | K14: User-supplied statement text | L14: 75.5 | M14: 2026-04-152317783031 | N14: Unique transaction
A15: 2026-04 | B15: 46114 | C15: Pagamento com QR Pix REDE BOM COMERCIO LTDA | D15: 152995794336 | E15: -112.27 | F15: Outflow | G15: Person / External Transfer | H15: Sent Pix | I15: REDE BOM COMERCIO LTDA | J15: 16463.26 | K15: User-supplied statement text | L15: 112.27 | M15: 2026-04-152995794336 | N15: Unique transaction
A16: 2026-04 | B16: 46114 | C16: Pagamento de conta Vivo Móvel SP | D16: 153040899150 | E16: -67.79 | F16: Outflow | G16: Telecommunications | H16: Mobile / telecom | I16: Vivo Móvel SP | J16: 16045.47 | K16: User-supplied statement text | L16: 67.79 | M16: 2026-04-153040899150 | N16: Unique transaction
... A73: 2026-05 | B73: 46146 | C73: Rendimentos | D73: 1743176355208 | E73: 11.65 | F73: Inflow | G73: Investment Yield | H73: Rendimentos | I73: Mercado Pago / Investment | J73: 23975.76 | K73: User-supplied statement text | L73: 11.65 | M73: 2026-05-1743176355208 | N73: Unique transaction
A74: 2026-05 | B74: 46147 | C74: Pagamento Cartão de crédito | D74: 157139914617 | E74: -8627.35 | F74: Outflow | G74: Credit Card Settlement | H74: Credit card | J74: 12875.06 | K74: User-supplied statement text | L74: 8627.35 | M74: 2026-05-157139914617 | N74: Unique transaction
A75: 2026-05 | B75: 46147 | C75: Pagamento SALUTARE MEDICINA E SAUDE | D75: 157802402212 | E75: -130.91 | F75: Outflow | G75: Health | H75: Health / pharmacy | I75: Pagamento SALUTARE MEDICINA E SAUDE | J75: 23675.09 | K75: User-supplied statement text | L75: 130.91 | M75: 2026-05-157802402212 | N75: Unique transaction
A76: 2026-05 | B76: 46147 | C76: Pix enviado Eduardo Silva dos Santos | D76: 157905028464 | E76: -450 | F76: Outflow | G76: Person / External Transfer | H76: Sent Pix | I76: Eduardo Silva dos Santos | J76: 23225.09 | K76: User-supplied statement text | L76: 450 | M76: 2026-05-157905028464 | N76: Unique transaction
A77: 2026-05 | B77: 46147 | C77: Pagamento Cartão de crédito | D77: 157907424040 | E77: -1722.68 | F77: Outflow | G77: Credit Card Settlement | H77: Credit card | J77: 21502.41 | K77: User-supplied statement text | L77: 1722.68 | M77: 2026-05-157907424040 | N77: Unique transaction
A78: 2026-05 | B78: 46147 | C78: Rendimentos | D78: 1743260411771 | E78: 10.24 | F78: Inflow | G78: Investment Yield | H78: Rendimentos | I78: Mercado Pago / Investment | J78: 23806 | K78: User-supplied statement text | L78: 10.24 | M78: 2026-05-1743260411771 | N78: Unique transaction
A79: 2026-05 | B79: 46148 | C79: Pagamento com QR Pix EDGLEY DE SOUSA FORMIGA | D79: 157214670055 | E79: -198.35 | F79: Outflow | G79: Person / External Transfer | H79: Sent Pix | I79: EDGLEY DE SOUSA FORMIGA | J79: 12454.45 | K79: User-supplied statement text | L79: 198.35 | M79: 2026-05-157214670055 | N79: Unique transaction
A80: 2026-05 | B80: 46148 | C80: Pix enviado Gleudson Silva Farias | D80: 157231141069 | E80: -1260 | F80: Outflow | G80: Person / External Transfer | H80: Sent Pix | I80: Gleudson Silva Farias | J80: 11194.45 | K80: User-supplied statement text | L80: 1260 | M80: 2026-05-157231141069 | N80: Unique transaction
A81: 2026-05 | B81: 46148 | C81: Pix enviado Casa dos Criadores Comercio Ltda | D81: 157252225025 | E81: -281 | F81: Outflow | G81: Purchases & Services | H81: Business / service | I81: Casa dos Criadores Comercio Ltda | J81: 10913.45 | K81: User-supplied statement text | L81: 281 | M81: 2026-05-157252225025 | N81: Unique transaction
A82: 2026-05 | B82: 46148 | C82: Pagamento com QR Pix MERCADINHO LACANTO LTDA | D82: 157981953362 | E82: -232.44 | F82: Outflow | G82: Groceries & Food | H82: Groceries / food | I82: MERCADINHO LACANTO LTDA | J82: 12652.8 | K82: User-supplied statement text | L82: 232.44 | M82: 2026-05-157981953362 | N82: Unique transaction
A83: 2026-05 | B83: 46148 | C83: Pix enviado Casa dos Criadores Comercio Ltda | D83: 158021830828 | E83: -15 | F83: Outflow | G83: Purchases & Services | H83: Business / service | I83: Casa dos Criadores Comercio Ltda | J83: 10898.45 | K83: User-supplied statement text | L83: 15 | M83: 2026-05-158021830828 | N83: Unique transaction
A84: 2026-05 | B84: 46148 | C84: Rendimentos | D84: 1743324850487 | E84: 10.18 | F84: Inflow | G84: Investment Yield | H84: Rendimentos | I84: Mercado Pago / Investment | J84: 12885.24 | K84: User-supplied statement text | L84: 10.18 | M84: 2026-05-1743324850487 | N84: Unique transaction
A85: 2026-05 | B85: 46149 | C85: Pagamento com QR Pix VINDI PAGAMENTOS SA | D85: 157467292465 | E85: -494.8 | F85: Outflow | G85: Purchases & Services | H85: Business / service | I85: VINDI PAGAMENTOS SA | J85: 10408.38 | K85: User-supplied statement text | L85: 494.8 | M85: 2026-05-157467292465 | N85: Unique transaction
A86: 2026-05 | B86: 46149 | C86: Rendimentos | D86: 1743387752167 | E86: 4.73 | F86: Inflow | G86: Investment Yield | H86: Rendimentos | I86: Mercado Pago / Investment | J86: 10903.18 | K86: User-supplied statement text | L86: 4.73 | M86: 2026-05-1743387752167 | N86: Unique transaction
A87: 2026-05 | B87: 46150 | C87: Pagamento com QR Pix PANIFICADORA SAO GONCALO LTDA | D87: 157566215629 | E87: -78.91 | F87: Outflow | G87: Groceries & Food | H87: Groceries / food | I87: PANIFICADORA SAO GONCALO LTDA | J87: 10082.76 | K87: User-supplied statement text | L87: 78.91 | M87: 2026-05-157566215629 | N87: Unique transaction
A88: 2026-05 | B88: 46150 | C88: Pagamento com QR Pix SUPERMERCADO LITORAL LTDA | D88: 157570731541 | E88: -430.42 | F88: Outflow | G88: Groceries & Food | H88: Groceries / food | I88: SUPERMERCADO LITORAL LTDA | J88: 9652.34 | K88: User-supplied statement text | L88: 430.42 | M88: 2026-05-157570731541 | N88: Unique transaction
A89: 2026-05 | B89: 46150 | C89: Pix enviado Eva Bezerra da Silva Brandao | D89: 157589983803 | E89: -1040 | F89: Outflow | G89: Person / External Transfer | H89: Sent Pix | I89: Eva Bezerra da Silva Brandao | J89: 8612.34 | K89: User-supplied statement text | L89: 1040 | M89: 2026-05-157589983803 | N89: Unique transaction
A90: 2026-05 | B90: 46150 | C90: Pagamento Mercado Libre | D90: 157607162465 | E90: -390.69 | F90: Outflow | G90: E-commerce | H90: Mercado Libre | J90: 8221.65 | K90: User-supplied statement text | L90: 390.69 | M90: 2026-05-157607162465 | N90: Unique transaction
A91: 2026-05 | B91: 46150 | C91: Pagamento de conta Vivo Móvel SP | D91: 158276307540 | E91: -251.43 | F91: Outflow | G91: Telecommunications | H91: Mobile / telecom | I91: Vivo Móvel SP | J91: 10161.67 | K91: User-supplied statement text | L91: 251.43 | M91: 2026-05-158276307540 | N91: Unique transaction
A92: 2026-05 | B92: 46150 | C92: Rendimentos | D92: 1743455883028 | E92: 4.72 | F92: Inflow | G92: Investment Yield | H92: Rendimentos | I92: Mercado Pago / Investment | J92: 10413.1 | K92: User-supplied statement text | L92: 4.72 | M92: 2026-05-1743455883028 | N92: Unique transaction
A93: 2026-05 | B93: 46151 | C93: Pagamento Mercado Libre | D93: 157692336095 | E93: -379.98 | F93: Outflow | G93: E-commerce | H93: Mercado Libre | J93: 7841.67 | K93: User-supplied statement text | L93: 379.98 | M93: 2026-05-157692336095 | N93: Unique transaction
A94: 2026-05 | B94: 46151 | C94: Pix enviado Eduardo Silva dos Santos | D94: 157713825511 | E94: -350 | F94: Outflow | G94: Person / External Transfer | H94: Sent Pix | I94: Eduardo Silva dos Santos | J94: 7491.67 | K94: User-supplied statement text | L94: 350 | M94: 2026-05-157713825511 | N94: Unique transaction
A95: 2026-05 | B95: 46152 | C95: Pix enviado Estacao 89 Comercio Varejista de Alimentos Ltda | D95: 158711310526 | E95: -97.1 | F95: Outflow | G95: Groceries & Food | H95: Groceries / food | I95: Estacao 89 Comercio Varejista de Alimentos Ltda | J95: 7394.57 | K95: User-supplied statement text | L95: 97.1 | M95: 2026-05-158711310526 | N95: Unique transaction
A96: 2026-05 | B96: 46153 | C96: Pix enviado MEGA BYTE COMPUTADORES | D96: 158738697878 | E96: -386.91 | F96: Outflow | G96: Purchases & Services | H96: Business / service | I96: MEGA BYTE COMPUTADORES | J96: 7011.22 | K96: User-supplied statement text | L96: 386.91 | M96: 2026-05-158738697878 | N96: Unique transaction
A97: 2026-05 | B97: 46153 | C97: Pagamento com QR Pix SECRETARIA DE ESTADO DA FAZENDA SEFAZ PB | D97: 158765690240 | E97: -1342.74 | F97: Outflow | G97: Taxes & Government | H97: Government | I97: SECRETARIA DE ESTADO DA FAZENDA SEFAZ PB | J97: 5668.48 | K97: User-supplied statement text | L97: 1342.74 | M97: 2026-05-158765690240 | N97: Unique transaction
...

Sheet Outflow Categories
A1: Outflow Categories
A2: Classification is analytical; transfers and credit-card settlements are separated from ordinary merchant consumption.
A4: Category | B4: Outflow Amount | C4: Share of Outflows | D4: Transaction Count
A5: Person / External Transfer | B5: 47343.84 | C5: 0.4131635 | D5: 89
A6: Credit Card Settlement | B6: 29540.63 | C6: 0.25779722 | D6: 5
A7: Bills & Services | B7: 9790.6 | C7: 0.085441287 | D7: 2
A8: Groceries & Food | B8: 6716.58 | C8: 0.058614716 | D8: 43
A9: E-commerce | B9: 4805.39 | C9: 0.041936011 | D9: 13
A10: Travel | B10: 3529.31 | C10: 0.030799827 | D10: 2
A11: Automotive | B11: 3340 | C11: 0.029147744 | D11: 2
A12: Purchases & Services | B12: 2096.13 | C12: 0.018292653 | D12: 8
A13: Dining | B13: 1448.9 | C13: 0.012644361 | D13: 12
A14: Taxes & Government | B14: 1342.74 | C14: 0.011717917 | D14: 1
A15: Utilities | B15: 1181.91 | C15: 0.010314374 | D15: 4
A16: Health | B16: 814.89 | C16: 0.0071114385 | D16: 5
... A24: Merchant Purchase | B24: 10 | C24: 8.7268693e-05 | D24: 1

Sheet Counterparties
A1: Counterparty Analysis
A2: Recurring names are aggregated across the five unique months.
A4: Counterparty | B4: Primary Category | C4: Transactions | D4: Net Amount | E4: Absolute Flow
B5: Credit Card Settlement | C5: 5 | D5: -29540.63 | E5: 29540.63
B6: E-commerce | C6: 13 | D6: -4805.39 | E6: 4805.39
A7: 52.875.146 VALDEBAM PROCOPIO DE ARAUJO | B7: Person / External Transfer | C7: 1 | D7: -73 | E7: 73
A8: 55.103.928 MARIA EDUARDA CARDOSO DA COSTA | B8: Person / External Transfer | C8: 1 | D8: -35 | E8: 35
A9: ATLANTICO SUL HOTELARIA E RESTAURANTES L | B9: Dining | C9: 1 | D9: -110 | E9: 110
A10: AUTO POSTO INTERMARES LTDA | B10: Fuel | C10: 1 | D10: -29.5 | E10: 29.5
A11: Amanda Gabrielle Freire De Souza | B11: Person / External Transfer | C11: 1 | D11: -131 | E11: 131
A12: B L SERVICE ADMINISTRADORA DE SERVICOS LTDA | B12: Person / External Transfer | C12: 1 | D12: -208 | E12: 208
A13: BANCO XP S.A | B13: Bills & Services | C13: 1 | D13: -9377.49 | E13: 9377.49
A14: BBP GASTRONOMIA LTDA | B14: Dining | C14: 1 | D14: -94.7 | E14: 94.7
A15: BUTIQUIM DO FORTAO LTDA | B15: Dining | C15: 3 | D15: -526.51 | E15: 526.51
A16: Bessa Express Loja De Proximidade Ltda | B16: Person / External Transfer | C16: 2 | D16: -69.45 | E16: 69.45
A17: Bianca Mikaella Nascimento Lima | B17: Person / External Transfer | C17: 5 | D17: -2570 | E17: 2570
A18: Br Brake Comercio e Servicos Automotivos Ltda | B18: Automotive | C18: 1 | D18: -3200 | E18: 3200
... A108: Williams Firmino dos Santos | B108: Person / External Transfer | C108: 1 | D108: -2085 | E108: 2085

Sheet Reconciliation
A1: Reconciliation & Source Control
A2: Statement totals are compared against the transaction ledger. Duplicate June source is documented but excluded.
A4: Source / Period | B4: Opening Balance | C4: Reported Inflows | D4: Calculated Inflows | E4: Inflows Variance | F4: Reported Outflows | G4: Calculated Outflows | H4: Outflows Variance | I4: Closing Balance | J4: Status
A5: April 2026 | B5: 21155.09 | C5: 27262.06 | D5: 27262.06 | E5: -3.6379788e-12 | F5: 21193.04 | G5: 21193.04 | H5: 0 | I5: 27224.11 | J5: PASS
A6: May 2026 | B6: 27224.11 | C6: 17065.63 | D6: 17065.63 | E6: -3.6379788e-12 | F6: 30217.29 | G6: 30217.29 | H6: 0 | I6: 14072.45 | J6: PASS
A7: June 2026 | B7: 14072.45 | C7: 24151.04 | D7: 24151.04 | E7: -3.6379788e-12 | F7: 14108.3 | G7: 14108.3 | H7: 0 | I7: 24115.19 | J7: PASS
A8: July 2026 | B8: 24115.19 | C8: 11272.89 | D8: 11272.89 | E8: 0 | F8: 31069.01 | G8: 31069.01 | H8: 3.6379788e-12 | I8: 4319.07 | J8: PASS
A9: August 2026 | B9: 4319.07 | C9: 25518.65 | D9: 25518.65 | E9: 0 | F9: 18000.99 | G9: 18000.99 | H9: -3.6379788e-12 | I9: 11836.73 | J9: PASS
A11: Source Register
A12: Source | B12: Period | C12: Role | D12: Workbook Treatment | E12: Transaction Detail
A13: MercadoPago.pdf | B13: June 2026 | C13: Unique month source | D13: Included | E13: 47 transactions
A14: MercadoPago 2.pdf | B14: August 2026 | C14: Unique month source | D14: Included | E14: 70 transactions
A15: MercadoPago 3.pdf | B15: July 2026 | C15: Unique month source | D15: Included | E15: 69 transactions
A16: MercadoPago 4.pdf | B16: June 2026 | C16: Duplicate of MercadoPago.pdf | D16: Excluded | E16: 0 added; duplicate
A17: User-supplied statement text | B17: May 2026 | C17: Statement content pasted in chat | D17: Included | E17: 76 transactions
A18: User-supplied statement text | B18: April 2026 | C18: Statement content pasted in chat | D18: Included | E18: 64 transactions

Sheet Analysis & Chat
A1: Analysis Log & Insights
A2: Condensed record of the analytical conclusions produced during the file-by-file review.
A4: Methodology
A5: • Applied the same procedure to each monthly statement: structure → data profile → inflows/outflows → liquidity trajectory → recurring counterparties → modeling distinctions → reconciliation.
A6: • Operation ID is retained as the transaction-level identifier.
A7: • Positive amounts are inflows; negative amounts are outflows; balance is the running balance.
A8: • Internal/self transfers are not automatically classified as income; credit-card settlements are not automatically treated as current-period consumption.
A10: April 2026
A11: • Opening R$21,155.09; inflows R$27,262.06; outflows R$21,193.04; closing R$27,224.11.
A12: • Dominant event: R$27,193.14 transfer received on Apr 30 after the balance fell to R$30.97.
A13: • Large Apr 9 outflows: R$3,235.00, R$3,200.00 and R$2,085.00.
A14: • Minimum observed balance: R$30.90. Reconciled.
... A52: • No transaction was fabricated to force reconciliation; the ledger is kept tied to supplied source data.
